[2025-06-15T07:03:16.793+0000] {taskinstance.py:1956} INFO - Dependencies all met for dep_context=non-requeueable deps ti=<TaskInstance: retail_analytics_airflowDAG.transform manual__2025-06-15T06:58:49.013896+00:00 [queued]>
[2025-06-15T07:03:16.804+0000] {taskinstance.py:1956} INFO - Dependencies all met for dep_context=requeueable deps ti=<TaskInstance: retail_analytics_airflowDAG.transform manual__2025-06-15T06:58:49.013896+00:00 [queued]>
[2025-06-15T07:03:16.805+0000] {taskinstance.py:2170} INFO - Starting attempt 4 of 4
[2025-06-15T07:03:16.829+0000] {taskinstance.py:2191} INFO - Executing <Task(PythonOperator): transform> on 2025-06-15 06:58:49.013896+00:00
[2025-06-15T07:03:16.838+0000] {standard_task_runner.py:60} INFO - Started process 267 to run task
[2025-06-15T07:03:16.842+0000] {standard_task_runner.py:87} INFO - Running: ['***', 'tasks', 'run', 'retail_analytics_***DAG', 'transform', 'manual__2025-06-15T06:58:49.013896+00:00', '--job-id', '14', '--raw', '--subdir', 'DAGS_FOLDER/etl_pipeline_dag.py', '--cfg-path', '/tmp/tmpck061764']
[2025-06-15T07:03:16.845+0000] {standard_task_runner.py:88} INFO - Job 14: Subtask transform
[2025-06-15T07:03:16.874+0000] {logging_mixin.py:188} WARNING - /home/***/.local/lib/python3.8/site-packages/***/settings.py:194 DeprecationWarning: The sql_alchemy_conn option in [core] has been moved to the sql_alchemy_conn option in [database] - the old setting has been used, but please update your config.
[2025-06-15T07:03:16.937+0000] {task_command.py:423} INFO - Running <TaskInstance: retail_analytics_airflowDAG.transform manual__2025-06-15T06:58:49.013896+00:00 [running]> on host 7bab5b7171c2
[2025-06-15T07:03:17.053+0000] {taskinstance.py:2480} INFO - Exporting env vars: AIRFLOW_CTX_DAG_OWNER='***' AIRFLOW_CTX_DAG_ID='retail_analytics_***DAG' AIRFLOW_CTX_TASK_ID='transform' AIRFLOW_CTX_EXECUTION_DATE='2025-06-15T06:58:49.013896+00:00' AIRFLOW_CTX_TRY_NUMBER='4' AIRFLOW_CTX_DAG_RUN_ID='manual__2025-06-15T06:58:49.013896+00:00'
[2025-06-15T07:03:17.055+0000] {data_transformation.py:12} INFO - Started transforming...
[2025-06-15T07:03:18.033+0000] {taskinstance.py:2698} ERROR - Task failed with exception
Traceback (most recent call last):
  File "/home/airflow/.local/lib/python3.8/site-packages/airflow/models/taskinstance.py", line 433, in _execute_task
    result = execute_callable(context=context, **execute_callable_kwargs)
  File "/home/airflow/.local/lib/python3.8/site-packages/airflow/operators/python.py", line 199, in execute
    return_value = self.execute_callable()
  File "/home/airflow/.local/lib/python3.8/site-packages/airflow/operators/python.py", line 216, in execute_callable
    return self.python_callable(*self.op_args, **self.op_kwargs)
  File "/opt/airflow/utils/data_transformation.py", line 21, in data_transformation
    customers_df['CustomerID'] = customers_df['CustomerID'].astype(int)
  File "/home/airflow/.local/lib/python3.8/site-packages/pandas/core/generic.py", line 6324, in astype
    new_data = self._mgr.astype(dtype=dtype, copy=copy, errors=errors)
  File "/home/airflow/.local/lib/python3.8/site-packages/pandas/core/internals/managers.py", line 451, in astype
    return self.apply(
  File "/home/airflow/.local/lib/python3.8/site-packages/pandas/core/internals/managers.py", line 352, in apply
    applied = getattr(b, f)(**kwargs)
  File "/home/airflow/.local/lib/python3.8/site-packages/pandas/core/internals/blocks.py", line 511, in astype
    new_values = astype_array_safe(values, dtype, copy=copy, errors=errors)
  File "/home/airflow/.local/lib/python3.8/site-packages/pandas/core/dtypes/astype.py", line 242, in astype_array_safe
    new_values = astype_array(values, dtype, copy=copy)
  File "/home/airflow/.local/lib/python3.8/site-packages/pandas/core/dtypes/astype.py", line 187, in astype_array
    values = _astype_nansafe(values, dtype, copy=copy)
  File "/home/airflow/.local/lib/python3.8/site-packages/pandas/core/dtypes/astype.py", line 138, in _astype_nansafe
    return arr.astype(dtype, copy=True)
ValueError: invalid literal for int() with base 10: 'Roy'
[2025-06-15T07:03:18.068+0000] {taskinstance.py:1138} INFO - Marking task as FAILED. dag_id=retail_analytics_***DAG, task_id=transform, execution_date=20250615T065849, start_date=20250615T070316, end_date=20250615T070318
[2025-06-15T07:03:18.111+0000] {standard_task_runner.py:107} ERROR - Failed to execute job 14 for task transform (invalid literal for int() with base 10: 'Roy'; 267)
[2025-06-15T07:03:18.141+0000] {local_task_job_runner.py:234} INFO - Task exited with return code 1
[2025-06-15T07:03:18.207+0000] {taskinstance.py:3280} INFO - 0 downstream tasks scheduled from follow-on schedule check
