[2025-06-15T07:07:32.334+0000] {taskinstance.py:1956} INFO - Dependencies all met for dep_context=non-requeueable deps ti=<TaskInstance: retail_analytics_airflowDAG.load manual__2025-06-15T07:04:43.328838+00:00 [queued]>
[2025-06-15T07:07:32.347+0000] {taskinstance.py:1956} INFO - Dependencies all met for dep_context=requeueable deps ti=<TaskInstance: retail_analytics_airflowDAG.load manual__2025-06-15T07:04:43.328838+00:00 [queued]>
[2025-06-15T07:07:32.348+0000] {taskinstance.py:2170} INFO - Starting attempt 2 of 4
[2025-06-15T07:07:32.373+0000] {taskinstance.py:2191} INFO - Executing <Task(PythonOperator): load> on 2025-06-15 07:04:43.328838+00:00
[2025-06-15T07:07:32.381+0000] {standard_task_runner.py:60} INFO - Started process 228 to run task
[2025-06-15T07:07:32.385+0000] {standard_task_runner.py:87} INFO - Running: ['***', 'tasks', 'run', 'retail_analytics_***DAG', 'load', 'manual__2025-06-15T07:04:43.328838+00:00', '--job-id', '20', '--raw', '--subdir', 'DAGS_FOLDER/etl_pipeline_dag.py', '--cfg-path', '/tmp/tmp9jovd8pj']
[2025-06-15T07:07:32.387+0000] {standard_task_runner.py:88} INFO - Job 20: Subtask load
[2025-06-15T07:07:32.420+0000] {logging_mixin.py:188} WARNING - /home/***/.local/lib/python3.8/site-packages/***/settings.py:194 DeprecationWarning: The sql_alchemy_conn option in [core] has been moved to the sql_alchemy_conn option in [database] - the old setting has been used, but please update your config.
[2025-06-15T07:07:32.463+0000] {task_command.py:423} INFO - Running <TaskInstance: retail_analytics_airflowDAG.load manual__2025-06-15T07:04:43.328838+00:00 [running]> on host 7bab5b7171c2
[2025-06-15T07:07:32.550+0000] {taskinstance.py:2480} INFO - Exporting env vars: AIRFLOW_CTX_DAG_OWNER='***' AIRFLOW_CTX_DAG_ID='retail_analytics_***DAG' AIRFLOW_CTX_TASK_ID='load' AIRFLOW_CTX_EXECUTION_DATE='2025-06-15T07:04:43.328838+00:00' AIRFLOW_CTX_TRY_NUMBER='2' AIRFLOW_CTX_DAG_RUN_ID='manual__2025-06-15T07:04:43.328838+00:00'
[2025-06-15T07:07:32.552+0000] {data_load_to_sql.py:25} INFO - Started loading...
[2025-06-15T07:08:00.442+0000] {logging_mixin.py:188} INFO - ✅ Table 'sales_gold' exists. Data appended.
[2025-06-15T07:08:00.780+0000] {logging_mixin.py:188} INFO - ✅ Table 'customers_gold' exists. Data appended.
[2025-06-15T07:08:00.966+0000] {logging_mixin.py:188} INFO - ✅ Table 'inventory_gold' exists. Data appended.
[2025-06-15T07:08:00.967+0000] {taskinstance.py:2698} ERROR - Task failed with exception
Traceback (most recent call last):
  File "/home/airflow/.local/lib/python3.8/site-packages/airflow/models/taskinstance.py", line 433, in _execute_task
    result = execute_callable(context=context, **execute_callable_kwargs)
  File "/home/airflow/.local/lib/python3.8/site-packages/airflow/operators/python.py", line 199, in execute
    return_value = self.execute_callable()
  File "/home/airflow/.local/lib/python3.8/site-packages/airflow/operators/python.py", line 216, in execute_callable
    return self.python_callable(*self.op_args, **self.op_kwargs)
  File "/opt/airflow/utils/data_load_to_sql.py", line 72, in load_to_sql
    conn.commit()
AttributeError: 'Connection' object has no attribute 'commit'
[2025-06-15T07:08:01.002+0000] {taskinstance.py:1138} INFO - Marking task as UP_FOR_RETRY. dag_id=retail_analytics_***DAG, task_id=load, execution_date=20250615T070443, start_date=20250615T070732, end_date=20250615T070801
[2025-06-15T07:08:01.035+0000] {standard_task_runner.py:107} ERROR - Failed to execute job 20 for task load ('Connection' object has no attribute 'commit'; 228)
[2025-06-15T07:08:01.122+0000] {local_task_job_runner.py:234} INFO - Task exited with return code 1
[2025-06-15T07:08:01.140+0000] {taskinstance.py:3280} INFO - 0 downstream tasks scheduled from follow-on schedule check
