[2025-06-15T07:06:02.244+0000] {taskinstance.py:1956} INFO - Dependencies all met for dep_context=non-requeueable deps ti=<TaskInstance: retail_analytics_airflowDAG.load manual__2025-06-15T07:04:43.328838+00:00 [queued]>
[2025-06-15T07:06:02.257+0000] {taskinstance.py:1956} INFO - Dependencies all met for dep_context=requeueable deps ti=<TaskInstance: retail_analytics_airflowDAG.load manual__2025-06-15T07:04:43.328838+00:00 [queued]>
[2025-06-15T07:06:02.258+0000] {taskinstance.py:2170} INFO - Starting attempt 1 of 4
[2025-06-15T07:06:02.284+0000] {taskinstance.py:2191} INFO - Executing <Task(PythonOperator): load> on 2025-06-15 07:04:43.328838+00:00
[2025-06-15T07:06:02.293+0000] {standard_task_runner.py:60} INFO - Started process 207 to run task
[2025-06-15T07:06:02.297+0000] {standard_task_runner.py:87} INFO - Running: ['***', 'tasks', 'run', 'retail_analytics_***DAG', 'load', 'manual__2025-06-15T07:04:43.328838+00:00', '--job-id', '19', '--raw', '--subdir', 'DAGS_FOLDER/etl_pipeline_dag.py', '--cfg-path', '/tmp/tmpn1r06afz']
[2025-06-15T07:06:02.299+0000] {standard_task_runner.py:88} INFO - Job 19: Subtask load
[2025-06-15T07:06:02.322+0000] {logging_mixin.py:188} WARNING - /home/***/.local/lib/python3.8/site-packages/***/settings.py:194 DeprecationWarning: The sql_alchemy_conn option in [core] has been moved to the sql_alchemy_conn option in [database] - the old setting has been used, but please update your config.
[2025-06-15T07:06:02.369+0000] {task_command.py:423} INFO - Running <TaskInstance: retail_analytics_airflowDAG.load manual__2025-06-15T07:04:43.328838+00:00 [running]> on host 7bab5b7171c2
[2025-06-15T07:06:02.492+0000] {taskinstance.py:2480} INFO - Exporting env vars: AIRFLOW_CTX_DAG_OWNER='***' AIRFLOW_CTX_DAG_ID='retail_analytics_***DAG' AIRFLOW_CTX_TASK_ID='load' AIRFLOW_CTX_EXECUTION_DATE='2025-06-15T07:04:43.328838+00:00' AIRFLOW_CTX_TRY_NUMBER='1' AIRFLOW_CTX_DAG_RUN_ID='manual__2025-06-15T07:04:43.328838+00:00'
[2025-06-15T07:06:02.494+0000] {data_load_to_sql.py:25} INFO - Started loading...
[2025-06-15T07:06:29.771+0000] {logging_mixin.py:188} INFO - ✅ Table 'sales_gold' created and data inserted.
[2025-06-15T07:06:30.397+0000] {logging_mixin.py:188} INFO - ✅ Table 'customers_gold' created and data inserted.
[2025-06-15T07:06:30.651+0000] {logging_mixin.py:188} INFO - ✅ Table 'inventory_gold' created and data inserted.
[2025-06-15T07:06:30.653+0000] {taskinstance.py:2698} ERROR - Task failed with exception
Traceback (most recent call last):
  File "/home/airflow/.local/lib/python3.8/site-packages/airflow/models/taskinstance.py", line 433, in _execute_task
    result = execute_callable(context=context, **execute_callable_kwargs)
  File "/home/airflow/.local/lib/python3.8/site-packages/airflow/operators/python.py", line 199, in execute
    return_value = self.execute_callable()
  File "/home/airflow/.local/lib/python3.8/site-packages/airflow/operators/python.py", line 216, in execute_callable
    return self.python_callable(*self.op_args, **self.op_kwargs)
  File "/opt/airflow/utils/data_load_to_sql.py", line 72, in load_to_sql
    conn.commit()
AttributeError: 'Connection' object has no attribute 'commit'
[2025-06-15T07:06:30.715+0000] {taskinstance.py:1138} INFO - Marking task as UP_FOR_RETRY. dag_id=retail_analytics_***DAG, task_id=load, execution_date=20250615T070443, start_date=20250615T070602, end_date=20250615T070630
[2025-06-15T07:06:30.762+0000] {standard_task_runner.py:107} ERROR - Failed to execute job 19 for task load ('Connection' object has no attribute 'commit'; 207)
[2025-06-15T07:06:30.857+0000] {local_task_job_runner.py:234} INFO - Task exited with return code 1
[2025-06-15T07:06:30.905+0000] {taskinstance.py:3280} INFO - 0 downstream tasks scheduled from follow-on schedule check
