[2025-06-15T03:22:53.221+0000] {taskinstance.py:1956} INFO - Dependencies all met for dep_context=non-requeueable deps ti=<TaskInstance: retail_analytics_airflowDAG.extract manual__2025-06-14T16:42:00.661490+00:00 [queued]>
[2025-06-15T03:22:53.234+0000] {taskinstance.py:1956} INFO - Dependencies all met for dep_context=requeueable deps ti=<TaskInstance: retail_analytics_airflowDAG.extract manual__2025-06-14T16:42:00.661490+00:00 [queued]>
[2025-06-15T03:22:53.235+0000] {taskinstance.py:2170} INFO - Starting attempt 3 of 4
[2025-06-15T03:22:53.271+0000] {taskinstance.py:2191} INFO - Executing <Task(PythonOperator): extract> on 2025-06-14 16:42:00.661490+00:00
[2025-06-15T03:22:53.279+0000] {standard_task_runner.py:60} INFO - Started process 215 to run task
[2025-06-15T03:22:53.288+0000] {standard_task_runner.py:87} INFO - Running: ['***', 'tasks', 'run', 'retail_analytics_***DAG', 'extract', 'manual__2025-06-14T16:42:00.661490+00:00', '--job-id', '10', '--raw', '--subdir', 'DAGS_FOLDER/etl_pipeline_dag.py', '--cfg-path', '/tmp/tmpplz8p0_8']
[2025-06-15T03:22:53.293+0000] {standard_task_runner.py:88} INFO - Job 10: Subtask extract
[2025-06-15T03:22:53.340+0000] {logging_mixin.py:188} WARNING - /home/***/.local/lib/python3.8/site-packages/***/settings.py:194 DeprecationWarning: The sql_alchemy_conn option in [core] has been moved to the sql_alchemy_conn option in [database] - the old setting has been used, but please update your config.
[2025-06-15T03:22:53.418+0000] {task_command.py:423} INFO - Running <TaskInstance: retail_analytics_airflowDAG.extract manual__2025-06-14T16:42:00.661490+00:00 [running]> on host 4a570cc26c41
[2025-06-15T03:22:53.623+0000] {taskinstance.py:2480} INFO - Exporting env vars: AIRFLOW_CTX_DAG_EMAIL='payalgoyaljuly2019@gmail.com' AIRFLOW_CTX_DAG_OWNER='***' AIRFLOW_CTX_DAG_ID='retail_analytics_***DAG' AIRFLOW_CTX_TASK_ID='extract' AIRFLOW_CTX_EXECUTION_DATE='2025-06-14T16:42:00.661490+00:00' AIRFLOW_CTX_TRY_NUMBER='3' AIRFLOW_CTX_DAG_RUN_ID='manual__2025-06-14T16:42:00.661490+00:00'
[2025-06-15T03:22:53.626+0000] {data_extract.py:14} INFO - Starting extraction...
[2025-06-15T03:22:53.642+0000] {taskinstance.py:2698} ERROR - Task failed with exception
Traceback (most recent call last):
  File "/home/airflow/.local/lib/python3.8/site-packages/pandas/compat/_optional.py", line 142, in import_optional_dependency
    module = importlib.import_module(name)
  File "/usr/local/lib/python3.8/importlib/__init__.py", line 127, in import_module
    return _bootstrap._gcd_import(name[level:], package, level)
  File "<frozen importlib._bootstrap>", line 1014, in _gcd_import
  File "<frozen importlib._bootstrap>", line 991, in _find_and_load
  File "<frozen importlib._bootstrap>", line 973, in _find_and_load_unlocked
ModuleNotFoundError: No module named 'openpyxl'

During handling of the above exception, another exception occurred:

Traceback (most recent call last):
  File "/home/airflow/.local/lib/python3.8/site-packages/airflow/models/taskinstance.py", line 433, in _execute_task
    result = execute_callable(context=context, **execute_callable_kwargs)
  File "/home/airflow/.local/lib/python3.8/site-packages/airflow/operators/python.py", line 199, in execute
    return_value = self.execute_callable()
  File "/home/airflow/.local/lib/python3.8/site-packages/airflow/operators/python.py", line 216, in execute_callable
    return self.python_callable(*self.op_args, **self.op_kwargs)
  File "/opt/airflow/utils/data_extract.py", line 15, in extract_data
    salesdf, customersdf, inventorydf = generate_data()
  File "/opt/airflow/utils/generate_data.py", line 14, in generate_data
    sales_df = pd.read_excel(os.path.join(project_root, 'data/loaded/loaded_sales_data.xlsx'), sheet_name='Online Retail')
  File "/home/airflow/.local/lib/python3.8/site-packages/pandas/io/excel/_base.py", line 478, in read_excel
    io = ExcelFile(io, storage_options=storage_options, engine=engine)
  File "/home/airflow/.local/lib/python3.8/site-packages/pandas/io/excel/_base.py", line 1513, in __init__
    self._reader = self._engines[engine](self._io, storage_options=storage_options)
  File "/home/airflow/.local/lib/python3.8/site-packages/pandas/io/excel/_openpyxl.py", line 548, in __init__
    import_optional_dependency("openpyxl")
  File "/home/airflow/.local/lib/python3.8/site-packages/pandas/compat/_optional.py", line 145, in import_optional_dependency
    raise ImportError(msg)
ImportError: Missing optional dependency 'openpyxl'.  Use pip or conda to install openpyxl.
[2025-06-15T03:22:53.668+0000] {taskinstance.py:1138} INFO - Marking task as UP_FOR_RETRY. dag_id=retail_analytics_***DAG, task_id=extract, execution_date=20250614T164200, start_date=20250615T032253, end_date=20250615T032253
[2025-06-15T03:22:53.691+0000] {logging_mixin.py:188} WARNING - /home/***/.local/lib/python3.8/site-packages/***/utils/email.py:154 RemovedInAirflow3Warning: Fetching SMTP credentials from configuration variables will be deprecated in a future release. Please set credentials using a connection instead.
[2025-06-15T03:22:53.692+0000] {configuration.py:1046} WARNING - section/key [smtp/smtp_user] not found in config
[2025-06-15T03:22:53.693+0000] {email.py:270} INFO - Email alerting: attempt 1
[2025-06-15T03:22:53.706+0000] {configuration.py:1046} WARNING - section/key [smtp/smtp_user] not found in config
[2025-06-15T03:22:53.707+0000] {email.py:270} INFO - Email alerting: attempt 1
[2025-06-15T03:22:53.708+0000] {taskinstance.py:826} ERROR - Failed to send email to: payalgoyaljuly2019@gmail.com
Traceback (most recent call last):
  File "/home/airflow/.local/lib/python3.8/site-packages/pandas/compat/_optional.py", line 142, in import_optional_dependency
    module = importlib.import_module(name)
  File "/usr/local/lib/python3.8/importlib/__init__.py", line 127, in import_module
    return _bootstrap._gcd_import(name[level:], package, level)
  File "<frozen importlib._bootstrap>", line 1014, in _gcd_import
  File "<frozen importlib._bootstrap>", line 991, in _find_and_load
  File "<frozen importlib._bootstrap>", line 973, in _find_and_load_unlocked
ModuleNotFoundError: No module named 'openpyxl'

During handling of the above exception, another exception occurred:

Traceback (most recent call last):
  File "/home/airflow/.local/lib/python3.8/site-packages/airflow/models/taskinstance.py", line 2334, in _run_raw_task
    self._execute_task_with_callbacks(context, test_mode, session=session)
  File "/home/airflow/.local/lib/python3.8/site-packages/airflow/models/taskinstance.py", line 2499, in _execute_task_with_callbacks
    result = self._execute_task(context, task_orig)
  File "/home/airflow/.local/lib/python3.8/site-packages/airflow/models/taskinstance.py", line 2516, in _execute_task
    return _execute_task(self, context, task_orig)
  File "/home/airflow/.local/lib/python3.8/site-packages/airflow/models/taskinstance.py", line 433, in _execute_task
    result = execute_callable(context=context, **execute_callable_kwargs)
  File "/home/airflow/.local/lib/python3.8/site-packages/airflow/operators/python.py", line 199, in execute
    return_value = self.execute_callable()
  File "/home/airflow/.local/lib/python3.8/site-packages/airflow/operators/python.py", line 216, in execute_callable
    return self.python_callable(*self.op_args, **self.op_kwargs)
  File "/opt/airflow/utils/data_extract.py", line 15, in extract_data
    salesdf, customersdf, inventorydf = generate_data()
  File "/opt/airflow/utils/generate_data.py", line 14, in generate_data
    sales_df = pd.read_excel(os.path.join(project_root, 'data/loaded/loaded_sales_data.xlsx'), sheet_name='Online Retail')
  File "/home/airflow/.local/lib/python3.8/site-packages/pandas/io/excel/_base.py", line 478, in read_excel
    io = ExcelFile(io, storage_options=storage_options, engine=engine)
  File "/home/airflow/.local/lib/python3.8/site-packages/pandas/io/excel/_base.py", line 1513, in __init__
    self._reader = self._engines[engine](self._io, storage_options=storage_options)
  File "/home/airflow/.local/lib/python3.8/site-packages/pandas/io/excel/_openpyxl.py", line 548, in __init__
    import_optional_dependency("openpyxl")
  File "/home/airflow/.local/lib/python3.8/site-packages/pandas/compat/_optional.py", line 145, in import_optional_dependency
    raise ImportError(msg)
ImportError: Missing optional dependency 'openpyxl'.  Use pip or conda to install openpyxl.

During handling of the above exception, another exception occurred:

Traceback (most recent call last):
  File "/home/airflow/.local/lib/python3.8/site-packages/airflow/models/taskinstance.py", line 1000, in _email_alert
    send_email(task.email, subject, html_content)
  File "/home/airflow/.local/lib/python3.8/site-packages/airflow/utils/email.py", line 80, in send_email
    return backend(
  File "/home/airflow/.local/lib/python3.8/site-packages/airflow/utils/email.py", line 154, in send_email_smtp
    send_mime_email(e_from=mail_from, e_to=recipients, mime_msg=msg, conn_id=conn_id, dryrun=dryrun)
  File "/home/airflow/.local/lib/python3.8/site-packages/airflow/utils/email.py", line 272, in send_mime_email
    smtp_conn = _get_smtp_connection(smtp_host, smtp_port, smtp_timeout, smtp_ssl)
  File "/home/airflow/.local/lib/python3.8/site-packages/airflow/utils/email.py", line 316, in _get_smtp_connection
    return smtplib.SMTP(host=host, port=port, timeout=timeout)
  File "/usr/local/lib/python3.8/smtplib.py", line 255, in __init__
    (code, msg) = self.connect(host, port)
  File "/usr/local/lib/python3.8/smtplib.py", line 339, in connect
    self.sock = self._get_socket(host, port, self.timeout)
  File "/usr/local/lib/python3.8/smtplib.py", line 310, in _get_socket
    return socket.create_connection((host, port), timeout,
  File "/usr/local/lib/python3.8/socket.py", line 808, in create_connection
    raise err
  File "/usr/local/lib/python3.8/socket.py", line 796, in create_connection
    sock.connect(sa)
ConnectionRefusedError: [Errno 111] Connection refused

During handling of the above exception, another exception occurred:

Traceback (most recent call last):
  File "/home/airflow/.local/lib/python3.8/site-packages/airflow/models/taskinstance.py", line 824, in _handle_failure
    task_instance.email_alert(error, failure_context["task"])
  File "/home/airflow/.local/lib/python3.8/site-packages/airflow/models/taskinstance.py", line 2946, in email_alert
    _email_alert(task_instance=self, exception=exception, task=task)
  File "/home/airflow/.local/lib/python3.8/site-packages/airflow/models/taskinstance.py", line 1002, in _email_alert
    send_email(task.email, subject, html_content_err)
  File "/home/airflow/.local/lib/python3.8/site-packages/airflow/utils/email.py", line 80, in send_email
    return backend(
  File "/home/airflow/.local/lib/python3.8/site-packages/airflow/utils/email.py", line 154, in send_email_smtp
    send_mime_email(e_from=mail_from, e_to=recipients, mime_msg=msg, conn_id=conn_id, dryrun=dryrun)
  File "/home/airflow/.local/lib/python3.8/site-packages/airflow/utils/email.py", line 272, in send_mime_email
    smtp_conn = _get_smtp_connection(smtp_host, smtp_port, smtp_timeout, smtp_ssl)
  File "/home/airflow/.local/lib/python3.8/site-packages/airflow/utils/email.py", line 316, in _get_smtp_connection
    return smtplib.SMTP(host=host, port=port, timeout=timeout)
  File "/usr/local/lib/python3.8/smtplib.py", line 255, in __init__
    (code, msg) = self.connect(host, port)
  File "/usr/local/lib/python3.8/smtplib.py", line 339, in connect
    self.sock = self._get_socket(host, port, self.timeout)
  File "/usr/local/lib/python3.8/smtplib.py", line 310, in _get_socket
    return socket.create_connection((host, port), timeout,
  File "/usr/local/lib/python3.8/socket.py", line 808, in create_connection
    raise err
  File "/usr/local/lib/python3.8/socket.py", line 796, in create_connection
    sock.connect(sa)
ConnectionRefusedError: [Errno 111] Connection refused
[2025-06-15T03:22:53.739+0000] {standard_task_runner.py:107} ERROR - Failed to execute job 10 for task extract (Missing optional dependency 'openpyxl'.  Use pip or conda to install openpyxl.; 215)
[2025-06-15T03:22:53.750+0000] {local_task_job_runner.py:234} INFO - Task exited with return code 1
[2025-06-15T03:22:53.785+0000] {taskinstance.py:3280} INFO - 0 downstream tasks scheduled from follow-on schedule check
