[2025-06-15T07:01:10.377+0000] {taskinstance.py:1956} INFO - Dependencies all met for dep_context=non-requeueable deps ti=<TaskInstance: retail_analytics_airflowDAG.transform scheduled__2025-06-14T00:00:00+00:00 [queued]>
[2025-06-15T07:01:10.398+0000] {taskinstance.py:1956} INFO - Dependencies all met for dep_context=requeueable deps ti=<TaskInstance: retail_analytics_airflowDAG.transform scheduled__2025-06-14T00:00:00+00:00 [queued]>
[2025-06-15T07:01:10.399+0000] {taskinstance.py:2170} INFO - Starting attempt 2 of 4
[2025-06-15T07:01:10.430+0000] {taskinstance.py:2191} INFO - Executing <Task(PythonOperator): transform> on 2025-06-14 00:00:00+00:00
[2025-06-15T07:01:10.439+0000] {standard_task_runner.py:60} INFO - Started process 230 to run task
[2025-06-15T07:01:10.444+0000] {standard_task_runner.py:87} INFO - Running: ['***', 'tasks', 'run', 'retail_analytics_***DAG', 'transform', 'scheduled__2025-06-14T00:00:00+00:00', '--job-id', '9', '--raw', '--subdir', 'DAGS_FOLDER/etl_pipeline_dag.py', '--cfg-path', '/tmp/tmp9fy8reva']
[2025-06-15T07:01:10.448+0000] {standard_task_runner.py:88} INFO - Job 9: Subtask transform
[2025-06-15T07:01:10.483+0000] {logging_mixin.py:188} WARNING - /home/***/.local/lib/python3.8/site-packages/***/settings.py:194 DeprecationWarning: The sql_alchemy_conn option in [core] has been moved to the sql_alchemy_conn option in [database] - the old setting has been used, but please update your config.
[2025-06-15T07:01:10.560+0000] {task_command.py:423} INFO - Running <TaskInstance: retail_analytics_airflowDAG.transform scheduled__2025-06-14T00:00:00+00:00 [running]> on host 7bab5b7171c2
[2025-06-15T07:01:10.789+0000] {taskinstance.py:2480} INFO - Exporting env vars: AIRFLOW_CTX_DAG_OWNER='***' AIRFLOW_CTX_DAG_ID='retail_analytics_***DAG' AIRFLOW_CTX_TASK_ID='transform' AIRFLOW_CTX_EXECUTION_DATE='2025-06-14T00:00:00+00:00' AIRFLOW_CTX_TRY_NUMBER='2' AIRFLOW_CTX_DAG_RUN_ID='scheduled__2025-06-14T00:00:00+00:00'
[2025-06-15T07:01:10.791+0000] {data_transformation.py:12} INFO - Started transforming...
[2025-06-15T07:01:12.042+0000] {taskinstance.py:2698} ERROR - Task failed with exception
Traceback (most recent call last):
  File "/home/airflow/.local/lib/python3.8/site-packages/airflow/models/taskinstance.py", line 433, in _execute_task
    result = execute_callable(context=context, **execute_callable_kwargs)
  File "/home/airflow/.local/lib/python3.8/site-packages/airflow/operators/python.py", line 199, in execute
    return_value = self.execute_callable()
  File "/home/airflow/.local/lib/python3.8/site-packages/airflow/operators/python.py", line 216, in execute_callable
    return self.python_callable(*self.op_args, **self.op_kwargs)
  File "/opt/airflow/utils/data_transformation.py", line 21, in data_transformation
    sales_cust_df = pd.merge(sales_df, customers_df, on='CustomerID', how='left')
  File "/home/airflow/.local/lib/python3.8/site-packages/pandas/core/reshape/merge.py", line 148, in merge
    op = _MergeOperation(
  File "/home/airflow/.local/lib/python3.8/site-packages/pandas/core/reshape/merge.py", line 741, in __init__
    self._maybe_coerce_merge_keys()
  File "/home/airflow/.local/lib/python3.8/site-packages/pandas/core/reshape/merge.py", line 1401, in _maybe_coerce_merge_keys
    raise ValueError(msg)
ValueError: You are trying to merge on int64 and object columns. If you wish to proceed you should use pd.concat
[2025-06-15T07:01:12.070+0000] {taskinstance.py:1138} INFO - Marking task as UP_FOR_RETRY. dag_id=retail_analytics_***DAG, task_id=transform, execution_date=20250614T000000, start_date=20250615T070110, end_date=20250615T070112
[2025-06-15T07:01:12.111+0000] {standard_task_runner.py:107} ERROR - Failed to execute job 9 for task transform (You are trying to merge on int64 and object columns. If you wish to proceed you should use pd.concat; 230)
[2025-06-15T07:01:12.146+0000] {local_task_job_runner.py:234} INFO - Task exited with return code 1
[2025-06-15T07:01:12.200+0000] {taskinstance.py:3280} INFO - 0 downstream tasks scheduled from follow-on schedule check
