[2025-06-15T10:27:32.061+0000] {taskinstance.py:1956} INFO - Dependencies all met for dep_context=non-requeueable deps ti=<TaskInstance: retail_analytics_airflowDAG.analyse manual__2025-06-15T10:26:11.682373+00:00 [queued]>
[2025-06-15T10:27:32.074+0000] {taskinstance.py:1956} INFO - Dependencies all met for dep_context=requeueable deps ti=<TaskInstance: retail_analytics_airflowDAG.analyse manual__2025-06-15T10:26:11.682373+00:00 [queued]>
[2025-06-15T10:27:32.075+0000] {taskinstance.py:2170} INFO - Starting attempt 1 of 4
[2025-06-15T10:27:32.091+0000] {taskinstance.py:2191} INFO - Executing <Task(PythonOperator): analyse> on 2025-06-15 10:26:11.682373+00:00
[2025-06-15T10:27:32.099+0000] {standard_task_runner.py:60} INFO - Started process 213 to run task
[2025-06-15T10:27:32.102+0000] {standard_task_runner.py:87} INFO - Running: ['***', 'tasks', 'run', 'retail_analytics_***DAG', 'analyse', 'manual__2025-06-15T10:26:11.682373+00:00', '--job-id', '31', '--raw', '--subdir', 'DAGS_FOLDER/etl_pipeline_dag.py', '--cfg-path', '/tmp/tmpg3oo1xxx']
[2025-06-15T10:27:32.104+0000] {standard_task_runner.py:88} INFO - Job 31: Subtask analyse
[2025-06-15T10:27:32.123+0000] {logging_mixin.py:188} WARNING - /home/***/.local/lib/python3.8/site-packages/***/settings.py:194 DeprecationWarning: The sql_alchemy_conn option in [core] has been moved to the sql_alchemy_conn option in [database] - the old setting has been used, but please update your config.
[2025-06-15T10:27:32.152+0000] {task_command.py:423} INFO - Running <TaskInstance: retail_analytics_airflowDAG.analyse manual__2025-06-15T10:26:11.682373+00:00 [running]> on host 6843dfc50be4
[2025-06-15T10:27:32.214+0000] {taskinstance.py:2480} INFO - Exporting env vars: AIRFLOW_CTX_DAG_OWNER='***' AIRFLOW_CTX_DAG_ID='retail_analytics_***DAG' AIRFLOW_CTX_TASK_ID='analyse' AIRFLOW_CTX_EXECUTION_DATE='2025-06-15T10:26:11.682373+00:00' AIRFLOW_CTX_TRY_NUMBER='1' AIRFLOW_CTX_DAG_RUN_ID='manual__2025-06-15T10:26:11.682373+00:00'
[2025-06-15T10:28:13.849+0000] {taskinstance.py:2698} ERROR - Task failed with exception
Traceback (most recent call last):
  File "/home/airflow/.local/lib/python3.8/site-packages/airflow/models/taskinstance.py", line 433, in _execute_task
    result = execute_callable(context=context, **execute_callable_kwargs)
  File "/home/airflow/.local/lib/python3.8/site-packages/airflow/operators/python.py", line 199, in execute
    return_value = self.execute_callable()
  File "/home/airflow/.local/lib/python3.8/site-packages/airflow/operators/python.py", line 216, in execute_callable
    return self.python_callable(*self.op_args, **self.op_kwargs)
  File "/opt/airflow/utils/data_analysis.py", line 147, in analysis
    top_products = top_selling_analysis(df)
TypeError: top_selling_analysis() takes 0 positional arguments but 1 was given
[2025-06-15T10:28:13.862+0000] {taskinstance.py:1138} INFO - Marking task as UP_FOR_RETRY. dag_id=retail_analytics_***DAG, task_id=analyse, execution_date=20250615T102611, start_date=20250615T102732, end_date=20250615T102813
[2025-06-15T10:28:13.875+0000] {standard_task_runner.py:107} ERROR - Failed to execute job 31 for task analyse (top_selling_analysis() takes 0 positional arguments but 1 was given; 213)
[2025-06-15T10:28:13.965+0000] {local_task_job_runner.py:234} INFO - Task exited with return code 1
[2025-06-15T10:28:13.990+0000] {taskinstance.py:3280} INFO - 0 downstream tasks scheduled from follow-on schedule check
